Workbook

Sheet Info
C1: 2024 | E1: 2023
A2: Assets | B2: Note | C2: R | E2: R
A4: Non-current assets | C4: =SUM(C5:C5) -> 9450000 | E4: =SUM(E5:E5) -> 4995000
A5: Property, plant and equipment | B5: 1 | C5: 9450000 | E5: 4995000
A7: Current assets | C7: =SUM(C8:C10) -> 269000 | E7: =SUM(E8:E10) -> 194750
A8: Trade and other receivables | C8: 247500 | E8: 189000
A9: Interest receivable | C9: 10250 | E9: 5750
A10: Cash and cash equivalents | C10: 11250 | E10: 0
A12: Total assets | C12: =C4+C7 -> 9719000 | E12: =E4+E7 -> 5189750
A14: Equity and liabilities
A16: Share capital | C16: 7798500 | E16: 4311000
A17: Retained earnings | C17: 469800 | E17: 73350
A18: Other components of equity | C18: 225000 | E18: 0
A20: Total equity | C20: =SUM(C16:C18) -> 8493300 | E20: =SUM(E16:E18) -> 4384350
A22: Non-current liabilities | C22: =SUM(C23:C23) -> 1182500 | E22: =SUM(E23:E23) -> 777500
A23: Borrowings | C23: 1182500 | E23: 777500
A25: Current liabilities | C25: =SUM(C26:C28) -> 43200 | E25: =SUM(E26:E28) -> 27900
A26: Trade and other payables | C26: 13500 | E26: 10800
A27: Bank overdraft | C27: 0 | E27: 5400
A28: Income tax payable | C28: 29700 | E28: 11700
A30: Total liabilities | C30: =C22+C25 -> 1225700 | E30: =E22+E25 -> 805400
A32: Total equity and liabilities | C32: =C30+C20 -> 9719000 | E32: =E30+E20 -> 5189750
A35: Check: | C35: =C32-C12 -> 0 | E35: =E32-E12 -> 0
C38: R
A39: Revenue | C39: 3375000
A40: Profit before tax | C40: 502200
A41: Tax expense | C41: 105750
A42: Depreciation | C42: 112500
A43: Interest income | C43: 38250
A44: Dividend income | C44: 27000
A45: Profit from the sale of equipment | C45: 22500

Sheet SCF
A1: CLOWNS (PTY) LTD.
A2: STATEMENT OF CASH FLOWS FOR THE YEAR ENDED 30 APRIL 2024 [1]
C3: R
A4: Cash flow from operating activities
A5: Cash receipts from customers (1) | C5: ='Calc 1+2'!B6 -> 3303000 | D5: [3]
A6: Cash paid to suppliers and employees (2) | C6: ='Calc 1+2'!B32 -> -2831850 | D6: [5]
A7: Cash generated from operations | C7: =SUM(C5:C6) -> 471150
A8: Tax paid (4) | C8: =-'Calc 3-6'!B23 -> -87750 | D8: [1.5]
C9: =SUM(C7:C8) -> 383400
A10: Cash flow from investing activities
A11: Purchase of fixed assets
A12: - Additions to land and buildings (5) | C12: =-'Calc 3-6'!B37 -> -4275000 | D12: [1.5]
A13: - Replacement of equipment (6) | C13: =-'Calc 3-6'!B51 -> -180000 | D13: [1.5]
A14: Proceeds on disposal of equipment | C14: 135000 | D14: [0.5]
A15: Interest received (3) | C15: ='Calc 3-6'!D9 -> 33750 | D15: [1.5]
A16: Dividends received | C16: =Info!C44 -> 27000 | D16: [0.5]
C17: =SUM(C12:C16) -> -4259250
A19: Cash flow from financing activities
A20: Proceeds from the issue of ordinary shares | C20: =Info!C16-Info!E16 -> 3487500 | D20: [1]
A21: Increase in long-term loans | C21: =Info!C23-Info!E23 -> 405000 | D21: [1]
C22: =SUM(C19:C21) -> 3892500
E23: Check:
A24: Net increase in cash and cash equivalents | C24: =C26-C25 -> 16650 | E24: =C9+C17+C22 -> 16650
A25: Cash and cash equivalents at beginning of year | C25: =-Info!E27 -> -5400 | D25: [1]
A26: Cash and cash equivalents at end of year | C26: =Info!C10 -> 11250
A28: Sub-totals and format | D28: [1]
A31: Notes for marker:
A32: - no format mark if abbreviations used in Statement of cash flows
A33: - If extra items in SCF (eg. depreciation): -0.5
A34: - If cash in-/outflow under wrong category: -0.5
A35: - If brackets wrong: -0.5
A36: - If tax paid and tax received: no marks
A37: - If interest paid and interest received: no marks (there was no interest paid in this question)
A38: - Investing activities: if no additions/expansion and replacement/maintaning: -0.5

Sheet Calc 1+2
A1: Calc 1
A3: Cash receipts from customers | E3: Debtors
A4: Revenue | B4: =Info!C39 -> 3375000 | C4: [0.5] | E4: O/B | F4: =189000+9000 -> 198000 | I4: [1] | J4: (189 000 + 9 000)
A5: (Increase) / decrease in debtors | B5: =-F6 -> -72000 | C5: [2.5]
B6: =SUM(B4:B5) -> 3303000 | E6: Bank | F6: =H8-F4 -> 72000 | I6: [0.5]m
A8: - If extra items in debtor account: -0.5 | G8: C/B | H8: =247500+22500 -> 270000 | I8: [1] | J8: (247 500 + 22 500)
A11: Calc 2 | E11: Alternative calculation
A13: Cash paid to suppliers and employees | E13: Cash paid to suppliers and employees
A14: Revenue | B14: =Info!C39 -> 3375000 | E14: Revenue | J14: 3375000
A15: Profit before tax | B15: =Info!C40 -> 502200 | C15: [1] | E15: Profit before tax | I15: 502200 | K15: [1]
A17: Net expenses | B17: =B15-B14 -> -2872800
A18: Adjust for non-cash items | E18: Adjust for non-cash items
A19: Movement in allowance for credit losses | B19: =22500-9000 -> 13500 | C19: [1] | D19: (22 500 - 9 000) | E19: Movement in allowance for credit losses | I19: 13500 | K19: [1]
A20: Depreciation | B20: =Info!C42 -> 112500 | C20: [0.5] | E20: Depreciation | I20: 112500 | K20: [0.5]
A21: Profit from the sale of equipment | B21: =-Info!C45 -> -22500 | C21: [0.5] | E21: Profit from the sale of equipment | J21: 22500 | K21: [0.5]
A23: Adjust for items shown elsewhere | E23: Adjust for items shown elsewhere
A24: Interest income | B24: =-Info!C43 -> -38250 | C24: [0.5] | E24: Interest income | J24: 38250 | K24: [0.5]
A25: Dividend income | B25: =-Info!C44 -> -27000 | C25: [0.5] | E25: Dividend income | J25: 27000 | K25: [0.5]
I26: =J27-I15-I19-I20 -> 2834550
A27: Net expenses | B27: =SUM(B17:B26) -> -2834550 | E27: Net expenses | I27: =J27 -> 3462750 | J27: =SUM(J14:J25) -> 3462750
A29: Adjust for working capital changes | E29: Adjust for working capital changes | I29: =-I26 -> -2834550
A30: Increase / (decrease) in creditors | B30: =Info!C26-Info!E26 -> 2700 | C30: [1] | E30: Increase / (decrease) in creditors | I30: 2700 | K30: [1]
A32: Net cash outflow | B32: =SUM(B27:B30) -> -2831850 | E32: Net cash outflow | I32: =SUM(I29:I31) -> -2831850
A36: - If brackets wrong: -0.5

Sheet Calc 3-6
A1: Calc 3
A3: Interest received
A5: Interest receivable
A6: O/B | B6: =Info!E9 -> 5750
A8: Interest income | B8: =Info!C43 -> 38250 | E8: [0.5]
C9: Bank | D9: =B11-D10 -> 33750 | E9: [0.5]m
C10: C/B | D10: =Info!C9 -> 10250 | E10: [0.5]
B11: =SUM(B6:B10) -> 44000
A15: Calc 4
A17: Tax paid
A19: Tax payable
C20: O/B | D20: =Info!E28 -> 11700
C22: Tax expense | D22: =Info!C41 -> 105750 | E22: [0.5]
A23: Bank | B23: =D25-B24 -> 87750 | E23: [0.5]m
A24: C/B | B24: =Info!C28 -> 29700 | E24: [0.5]
B25: =SUM(B20:B24) -> 117450 | D25: =SUM(D20:D24) -> 117450
A29: Calc 5
A31: Additions to land and buildings
A33: Buildings
A34: O/B | B34: 4500000
A36: Revaluation | B36: =Info!C18-Info!E18 -> 225000 | E36: [0.5]
A37: Bank | B37: =D39-B34-B36 -> 4275000 | E37: [0.5]m
C38: C/B | D38: 9000000 | E38: [0.5]
B39: =SUM(B34:B38) -> 9000000 | D39: =SUM(D34:D38) -> 9000000
A43: Calc 6
A45: Replacement of equipment
A47: Equipment
A48: O/B | B48: 900000
C49: Asset realisation | D49: 180000 | E49: [0.5]
A51: Bank | B51: =D53-B48-B50 -> 180000 | E51: [0.5]m
C52: C/B | D52: 900000 | E52: [0.5]
B53: =SUM(B48:B52) -> 1080000 | D53: =SUM(D48:D52) -> 1080000
A57: Check: equipment + depreciation (not required)
A59: Proceeds on disposal of equipment
A61: Cost price | C61: 180000
A62: Acc depreciation | C62: =C63-C61 -> -67500
A63: Carrying amount | C63: =C64-C65 -> 112500
A64: Cash | C64: 135000
A65: Profit | C65: =Info!C45 -> 22500
A68: Accummulated depreciation
...
